<?xml version="1.0" encoding="utf-8"?>
<!-- This URDF was automatically created by SolidWorks to URDF Exporter! Originally created by Stephen Brawner (brawner@gmail.com) 
     Commit Version: 1.6.0-4-g7f85cfe  Build Version: 1.6.7995.38578
     For more information, please see http://wiki.ros.org/sw_urdf_exporter -->
<robot
  name="Lever Action Valve_17">
  <link
    name="Joint1">
    <inertial>
      <origin
        xyz="-0.0612969161199989 -0.0208110471960751 -0.00368566958444174"
        rpy="0 0 0" />
      <mass
        value="0.509220112347729" />
      <inertia
        ixx="0.0130737320923455"
        ixy="9.45756252899026E-11"
        ixz="-1.48811108482286E-05"
        iyy="0.0130795076292887"
        iyz="-4.67801496593558E-11"
        izz="0.000230266745105746" />
    </inertial>
    <visual>
      <origin
        xyz="0 0 0"
        rpy="0 0 0" />
      <geometry>
        <mesh
          filename="package://Lever Action Valve_17/meshes/Joint1.STL" />
      </geometry>
      <material
        name="">
        <color
          rgba="0.792156862745098 0.819607843137255 0.933333333333333 1" />
      </material>
    </visual>
    <collision>
      <origin
        xyz="0 0 0"
        rpy="0 0 0" />
      <geometry>
        <mesh
          filename="package://Lever Action Valve_17/meshes/Joint1.STL" />
      </geometry>
    </collision>
  </link>
  <link
    name="Joint2">
    <inertial>
      <origin
        xyz="-0.0226040077206507 -1.2490009027033E-16 -2.08166817117217E-17"
        rpy="0 0 0" />
      <mass
        value="0.0292003183169538" />
      <inertia
        ixx="2.66087900663241E-06"
        ixy="-1.82047389576919E-20"
        ixz="9.71278719685466E-39"
        iyy="7.65960849851593E-06"
        iyz="-7.56029715497403E-39"
        izz="7.65960849851593E-06" />
    </inertial>
    <visual>
      <origin
        xyz="0 0 0"
        rpy="0 0 0" />
      <geometry>
        <mesh
          filename="package://Lever Action Valve_17/meshes/Joint2.STL" />
      </geometry>
      <material
        name="">
        <color
          rgba="0.792156862745098 0.819607843137255 0.933333333333333 1" />
      </material>
    </visual>
    <collision>
      <origin
        xyz="0 0 0"
        rpy="0 0 0" />
      <geometry>
        <mesh
          filename="package://Lever Action Valve_17/meshes/Joint2.STL" />
      </geometry>
    </collision>
  </link>
  <joint
    name="Joint2"
    type="fixed">
    <origin
      xyz="0 -0.0208110485691569 0.0701492821564897"
      rpy="1.5707963267949 0 0" />
    <parent
      link="Joint1" />
    <child
      link="Joint2" />
    <axis
      xyz="1 0 0" />
    <limit
      lower="0"
      upper="1.5708"
      effort="0"
      velocity="0" />
  </joint>
  <link
    name="joint3">
    <inertial>
      <origin
        xyz="-0.0098266311138373 -4.78783679369599E-16 0.0394973851429148"
        rpy="0 0 0" />
      <mass
        value="0.0244780463145089" />
      <inertia
        ixx="4.8921091480238E-05"
        ixy="1.09320733411926E-20"
        ixz="-7.13368201305606E-07"
        iyy="4.85761024631166E-05"
        iyz="4.78440318615536E-19"
        izz="2.65296409921423E-06" />
    </inertial>
    <visual>
      <origin
        xyz="0 0 0"
        rpy="0 0 0" />
      <geometry>
        <mesh
          filename="package://Lever Action Valve_17/meshes/joint3.STL" />
      </geometry>
      <material
        name="">
        <color
          rgba="0.792156862745098 0.819607843137255 0.933333333333333 1" />
      </material>
    </visual>
    <collision>
      <origin
        xyz="0 0 0"
        rpy="0 0 0" />
      <geometry>
        <mesh
          filename="package://Lever Action Valve_17/meshes/joint3.STL" />
      </geometry>
    </collision>
  </link>
  <joint
    name="joint3"
    type="revolute">
    <origin
      xyz="0 0 0"
      rpy="-1.5708 0 0" />
    <parent
      link="Joint2" />
    <child
      link="joint3" />
    <axis
      xyz="1 0 0" />
    <limit
      lower="-1.570796"
      upper="0"
      effort="0"
      velocity="0" />
  </joint>
</robot>